<?xml version="1.0"?>
<robot name="sample_robot">

  <!-- ── links ──────────────────────────────────────────────────────────── -->

  <link name="base_link"/>

  <link name="shoulder_link">
    <inertial>
      <mass value="1.2"/>
      <inertia ixx="0.01" ixy="0.0" ixz="0.0" iyy="0.01" iyz="0.0" izz="0.005"/>
    </inertial>
  </link>

  <link name="elbow_link">
    <inertial>
      <mass value="0.8"/>
      <inertia ixx="0.005" ixy="0.0" ixz="0.0" iyy="0.005" iyz="0.0" izz="0.003"/>
    </inertial>
  </link>

  <link name="wrist_link">
    <inertial>
      <mass value="0.4"/>
      <inertia ixx="0.002" ixy="0.0" ixz="0.0" iyy="0.002" iyz="0.0" izz="0.001"/>
    </inertial>
  </link>

  <link name="tool_link"/>

  <!-- ── joints ─────────────────────────────────────────────────────────── -->

  <joint name="shoulder_pan_joint" type="revolute">
    <parent link="base_link"/>
    <child  link="shoulder_link"/>
    <origin xyz="0 0 0.1" rpy="0 0 0"/>
    <axis   xyz="0 0 1"/>
    <limit  lower="-3.14159" upper="3.14159" effort="50.0" velocity="2.0"/>
  </joint>

  <joint name="elbow_joint" type="revolute">
    <parent link="shoulder_link"/>
    <child  link="elbow_link"/>
    <origin xyz="0.3 0 0" rpy="0 0 0"/>
    <axis   xyz="0 1 0"/>
    <limit  lower="-1.5708" upper="1.5708" effort="30.0" velocity="2.0"/>
  </joint>

  <joint name="wrist_joint" type="revolute">
    <parent link="elbow_link"/>
    <child  link="wrist_link"/>
    <origin xyz="0.25 0 0" rpy="0 0 0"/>
    <axis   xyz="0 1 0"/>
    <limit  lower="-1.5708" upper="1.5708" effort="10.0" velocity="3.0"/>
  </joint>

  <joint name="tool_joint" type="fixed">
    <parent link="wrist_link"/>
    <child  link="tool_link"/>
    <origin xyz="0.05 0 0" rpy="0 0 0"/>
  </joint>

  <!-- ── ros2_control ───────────────────────────────────────────────────── -->

  <ros2_control name="robot_system" type="system">

    <!-- Position-controlled revolute joint (full state feedback) -->
    <joint name="shoulder_pan_joint">
      <command_interface name="position"/>
      <state_interface   name="position"/>
      <state_interface   name="velocity"/>
      <state_interface   name="effort"/>
    </joint>

    <!-- Velocity-controlled joint (e.g. conveyor / wheel) -->
    <joint name="elbow_joint">
      <command_interface name="velocity"/>
      <state_interface   name="velocity"/>
      <state_interface   name="effort"/>
    </joint>

    <!-- Position + effort (torque-controlled wrist) -->
    <joint name="wrist_joint">
      <command_interface name="position"/>
      <command_interface name="effort"/>
      <state_interface   name="position"/>
      <state_interface   name="velocity"/>
      <state_interface   name="effort"/>
    </joint>

    <!-- IMU mounted on the base -->
    <sensor name="base_imu">
      <state_interface name="linear_acceleration.x"/>
      <state_interface name="linear_acceleration.y"/>
      <state_interface name="linear_acceleration.z"/>
      <state_interface name="angular_velocity.x"/>
      <state_interface name="angular_velocity.y"/>
      <state_interface name="angular_velocity.z"/>
    </sensor>

    <!-- Tool GPIO: vacuum on/off command, pressure + error status readback -->
    <gpio name="tool_gpio">
      <command_interface name="gpio/vacuum_enable" value_type="bool"/>
      <state_interface   name="gpio/vacuum_pressure"/>
      <state_interface   name="gpio/error_status"/>
    </gpio>

  </ros2_control>

</robot>
